Traceback (most recent call last):
  File "/usr/lib/python2.7/runpy.py", line 162, in _run_module_as_main
    "__main__", fname, loader, pkg_name)
  File "/usr/lib/python2.7/runpy.py", line 72, in _run_code
    exec code in run_globals
  File "/home/ubuntu/RCloud/RCProj/ServerD/echoS.py", line 193, in <module>
    sock.bind(server_address)
  File "/usr/lib/python2.7/socket.py", line 224, in meth
    return getattr(self._sock,name)(*args)
socket.error: [Errno 98] Address already in use
Traceback (most recent call last):
  File "/usr/lib/python2.7/runpy.py", line 162, in _run_module_as_main
    "__main__", fname, loader, pkg_name)
  File "/usr/lib/python2.7/runpy.py", line 72, in _run_code
    exec code in run_globals
  File "/home/ubuntu/RCloud/RCProj/ServerD/echoS.py", line 193, in <module>
    sock.bind(server_address)
  File "/usr/lib/python2.7/socket.py", line 224, in meth
    return getattr(self._sock,name)(*args)
socket.error: [Errno 98] Address already in use
Traceback (most recent call last):
  File "/usr/lib/python2.7/runpy.py", line 162, in _run_module_as_main
    "__main__", fname, loader, pkg_name)
  File "/usr/lib/python2.7/runpy.py", line 72, in _run_code
    exec code in run_globals
  File "/home/ubuntu/RCloud/RCProj/ServerD/echoS.py", line 193, in <module>
    sock.bind(server_address)
  File "/usr/lib/python2.7/socket.py", line 224, in meth
    return getattr(self._sock,name)(*args)
socket.error: [Errno 98] Address already in use
Traceback (most recent call last):
  File "/usr/lib/python2.7/runpy.py", line 162, in _run_module_as_main
    "__main__", fname, loader, pkg_name)
  File "/usr/lib/python2.7/runpy.py", line 72, in _run_code
    exec code in run_globals
  File "/home/ubuntu/RCloud/RCProj/ServerD/echoS.py", line 193, in <module>
    sock.bind(server_address)
  File "/usr/lib/python2.7/socket.py", line 224, in meth
    return getattr(self._sock,name)(*args)
socket.error: [Errno 98] Address already in use
Traceback (most recent call last):
  File "/usr/lib/python2.7/runpy.py", line 162, in _run_module_as_main
    "__main__", fname, loader, pkg_name)
  File "/usr/lib/python2.7/runpy.py", line 72, in _run_code
    exec code in run_globals
  File "/home/ubuntu/RCloud/RCProj/ServerD/echoS.py", line 193, in <module>
    sock.bind(server_address)
  File "/usr/lib/python2.7/socket.py", line 224, in meth
    return getattr(self._sock,name)(*args)
socket.error: [Errno 98] Address already in use
Traceback (most recent call last):
  File "/usr/lib/python2.7/runpy.py", line 162, in _run_module_as_main
    "__main__", fname, loader, pkg_name)
  File "/usr/lib/python2.7/runpy.py", line 72, in _run_code
    exec code in run_globals
  File "/home/ubuntu/RCloud/RCProj/ServerD/echoS.py", line 193, in <module>
    sock.bind(server_address)
  File "/usr/lib/python2.7/socket.py", line 224, in meth
    return getattr(self._sock,name)(*args)
socket.error: [Errno 98] Address already in use
Traceback (most recent call last):
  File "/usr/lib/python2.7/runpy.py", line 162, in _run_module_as_main
    "__main__", fname, loader, pkg_name)
  File "/usr/lib/python2.7/runpy.py", line 72, in _run_code
    exec code in run_globals
  File "/home/ubuntu/RCloud/RCProj/ServerD/echoS.py", line 193, in <module>
    sock.bind(server_address)
  File "/usr/lib/python2.7/socket.py", line 224, in meth
    return getattr(self._sock,name)(*args)
socket.error: [Errno 98] Address already in use
Traceback (most recent call last):
  File "/usr/lib/python2.7/runpy.py", line 162, in _run_module_as_main
    "__main__", fname, loader, pkg_name)
  File "/usr/lib/python2.7/runpy.py", line 72, in _run_code
    exec code in run_globals
  File "/home/ubuntu/RCloud/RCProj/ServerD/echoS.py", line 193, in <module>
    sock.bind(server_address)
  File "/usr/lib/python2.7/socket.py", line 224, in meth
    return getattr(self._sock,name)(*args)
socket.error: [Errno 98] Address already in use
Traceback (most recent call last):
  File "/usr/lib/python2.7/runpy.py", line 162, in _run_module_as_main
    "__main__", fname, loader, pkg_name)
  File "/usr/lib/python2.7/runpy.py", line 72, in _run_code
    exec code in run_globals
  File "/home/ubuntu/RCloud/RCProj/ServerD/echoS.py", line 193, in <module>
    sock.bind(server_address)
  File "/usr/lib/python2.7/socket.py", line 224, in meth
    return getattr(self._sock,name)(*args)
socket.error: [Errno 98] Address already in use
Traceback (most recent call last):
  File "/usr/lib/python2.7/runpy.py", line 162, in _run_module_as_main
    "__main__", fname, loader, pkg_name)
  File "/usr/lib/python2.7/runpy.py", line 72, in _run_code
    exec code in run_globals
  File "/home/ubuntu/RCloud/RCProj/ServerD/echoS.py", line 193, in <module>
    sock.bind(server_address)
  File "/usr/lib/python2.7/socket.py", line 224, in meth
    return getattr(self._sock,name)(*args)
socket.error: [Errno 98] Address already in use
Traceback (most recent call last):
  File "/usr/lib/python2.7/runpy.py", line 162, in _run_module_as_main
    "__main__", fname, loader, pkg_name)
  File "/usr/lib/python2.7/runpy.py", line 72, in _run_code
    exec code in run_globals
  File "/home/ubuntu/RCloud/RCProj/ServerD/echoS.py", line 193, in <module>
    sock.bind(server_address)
  File "/usr/lib/python2.7/socket.py", line 224, in meth
    return getattr(self._sock,name)(*args)
socket.error: [Errno 98] Address already in use
Traceback (most recent call last):
  File "/usr/lib/python2.7/runpy.py", line 162, in _run_module_as_main
    "__main__", fname, loader, pkg_name)
  File "/usr/lib/python2.7/runpy.py", line 72, in _run_code
    exec code in run_globals
  File "/home/ubuntu/RCloud/RCProj/ServerD/echoS.py", line 193, in <module>
    sock.bind(server_address)
  File "/usr/lib/python2.7/socket.py", line 224, in meth
    return getattr(self._sock,name)(*args)
socket.error: [Errno 98] Address already in use
Traceback (most recent call last):
  File "/usr/lib/python2.7/runpy.py", line 162, in _run_module_as_main
    "__main__", fname, loader, pkg_name)
  File "/usr/lib/python2.7/runpy.py", line 72, in _run_code
    exec code in run_globals
  File "/home/ubuntu/RCloud/RCProj/ServerD/echoS.py", line 193, in <module>
    sock.bind(server_address)
  File "/usr/lib/python2.7/socket.py", line 224, in meth
    return getattr(self._sock,name)(*args)
socket.error: [Errno 98] Address already in use
Traceback (most recent call last):
  File "/usr/lib/python2.7/runpy.py", line 162, in _run_module_as_main
    "__main__", fname, loader, pkg_name)
  File "/usr/lib/python2.7/runpy.py", line 72, in _run_code
    exec code in run_globals
  File "/home/ubuntu/RCloud/RCProj/ServerD/echoS.py", line 193, in <module>
    sock.bind(server_address)
  File "/usr/lib/python2.7/socket.py", line 224, in meth
    return getattr(self._sock,name)(*args)
socket.error: [Errno 98] Address already in use
Traceback (most recent call last):
  File "/usr/lib/python2.7/runpy.py", line 162, in _run_module_as_main
    "__main__", fname, loader, pkg_name)
  File "/usr/lib/python2.7/runpy.py", line 72, in _run_code
    exec code in run_globals
  File "/home/ubuntu/RCloud/RCProj/ServerD/echoS.py", line 193, in <module>
    sock.bind(server_address)
  File "/usr/lib/python2.7/socket.py", line 224, in meth
    return getattr(self._sock,name)(*args)
socket.error: [Errno 98] Address already in use
Traceback (most recent call last):
  File "/usr/lib/python2.7/runpy.py", line 162, in _run_module_as_main
    "__main__", fname, loader, pkg_name)
  File "/usr/lib/python2.7/runpy.py", line 72, in _run_code
    exec code in run_globals
  File "/home/ubuntu/RCloud/RCProj/ServerD/echoS.py", line 193, in <module>
    sock.bind(server_address)
  File "/usr/lib/python2.7/socket.py", line 224, in meth
    return getattr(self._sock,name)(*args)
socket.error: [Errno 98] Address already in use
Traceback (most recent call last):
  File "/usr/lib/python2.7/runpy.py", line 162, in _run_module_as_main
    "__main__", fname, loader, pkg_name)
  File "/usr/lib/python2.7/runpy.py", line 72, in _run_code
    exec code in run_globals
  File "/home/ubuntu/RCloud/RCProj/ServerD/echoS.py", line 190, in <module>
    socket.setsockopt(socket.SOL_SOCKET,socket.SO_RESUSEADDR,1)
AttributeError: 'module' object has no attribute 'setsockopt'
Traceback (most recent call last):
  File "/usr/lib/python2.7/runpy.py", line 162, in _run_module_as_main
    "__main__", fname, loader, pkg_name)
  File "/usr/lib/python2.7/runpy.py", line 72, in _run_code
    exec code in run_globals
  File "/home/ubuntu/RCloud/RCProj/ServerD/echoS.py", line 190, in <module>
    socket.setsockopt(socket.SOL_SOCKET,socket.SO_RESUSEADDR,1)
AttributeError: 'module' object has no attribute 'setsockopt'
Traceback (most recent call last):
  File "/usr/lib/python2.7/runpy.py", line 162, in _run_module_as_main
    "__main__", fname, loader, pkg_name)
  File "/usr/lib/python2.7/runpy.py", line 72, in _run_code
    exec code in run_globals
  File "/home/ubuntu/RCloud/RCProj/ServerD/echoS.py", line 190, in <module>
    socket.setsockopt(socket.SOL_SOCKET,socket.SO_RESUSEADDR,1)
AttributeError: 'module' object has no attribute 'setsockopt'
Traceback (most recent call last):
  File "/usr/lib/python2.7/runpy.py", line 162, in _run_module_as_main
    "__main__", fname, loader, pkg_name)
  File "/usr/lib/python2.7/runpy.py", line 72, in _run_code
    exec code in run_globals
  File "/home/ubuntu/RCloud/RCProj/ServerD/echoS.py", line 190, in <module>
    socket.setsockopt(socket.SOL_SOCKET,socket.SO_RESUSEADDR,1)
AttributeError: 'module' object has no attribute 'setsockopt'
Traceback (most recent call last):
  File "/usr/lib/python2.7/runpy.py", line 162, in _run_module_as_main
    "__main__", fname, loader, pkg_name)
  File "/usr/lib/python2.7/runpy.py", line 72, in _run_code
    exec code in run_globals
  File "/home/ubuntu/RCloud/RCProj/ServerD/echoS.py", line 193, in <module>
    sock.setsockopt(socket.SOL_SOCKET,socket.SO_RESUSEADDR,1)
AttributeError: 'module' object has no attribute 'SO_RESUSEADDR'
Traceback (most recent call last):
  File "/usr/lib/python2.7/runpy.py", line 162, in _run_module_as_main
    "__main__", fname, loader, pkg_name)
  File "/usr/lib/python2.7/runpy.py", line 72, in _run_code
    exec code in run_globals
  File "/home/ubuntu/RCloud/RCProj/ServerD/echoS.py", line 193, in <module>
    sock.setsockopt(socket.SOL_SOCKET,socket.SO_RESUSEADDR,1)
AttributeError: 'module' object has no attribute 'SO_RESUSEADDR'
Traceback (most recent call last):
  File "/usr/lib/python2.7/runpy.py", line 162, in _run_module_as_main
    "__main__", fname, loader, pkg_name)
  File "/usr/lib/python2.7/runpy.py", line 72, in _run_code
    exec code in run_globals
  File "/home/ubuntu/RCloud/RCProj/ServerD/echoS.py", line 193, in <module>
    sock.setsockopt(socket.SOL_SOCKET,socket.SO_RESUSEADDR,1)
AttributeError: 'module' object has no attribute 'SO_RESUSEADDR'
Traceback (most recent call last):
  File "/usr/lib/python2.7/runpy.py", line 162, in _run_module_as_main
    "__main__", fname, loader, pkg_name)
  File "/usr/lib/python2.7/runpy.py", line 72, in _run_code
    exec code in run_globals
  File "/home/ubuntu/RCloud/RCProj/ServerD/echoS.py", line 193, in <module>
    sock.setsockopt(socket.SOL_SOCKET,socket.SO_RESUSEADDR,1)
AttributeError: 'module' object has no attribute 'SO_RESUSEADDR'
Traceback (most recent call last):
  File "/usr/lib/python2.7/runpy.py", line 162, in _run_module_as_main
    "__main__", fname, loader, pkg_name)
  File "/usr/lib/python2.7/runpy.py", line 72, in _run_code
    exec code in run_globals
  File "/home/ubuntu/RCloud/RCProj/ServerD/echoS.py", line 196, in <module>
    sock.bind(server_address)
  File "/usr/lib/python2.7/socket.py", line 224, in meth
    return getattr(self._sock,name)(*args)
socket.error: [Errno 98] Address already in use
Traceback (most recent call last):
  File "/usr/lib/python2.7/runpy.py", line 162, in _run_module_as_main
    "__main__", fname, loader, pkg_name)
  File "/usr/lib/python2.7/runpy.py", line 72, in _run_code
    exec code in run_globals
  File "/home/ubuntu/RCloud/RCProj/ServerD/echoS.py", line 196, in <module>
    sock.bind(server_address)
  File "/usr/lib/python2.7/socket.py", line 224, in meth
    return getattr(self._sock,name)(*args)
socket.error: [Errno 98] Address already in use
Traceback (most recent call last):
  File "/usr/lib/python2.7/runpy.py", line 162, in _run_module_as_main
    "__main__", fname, loader, pkg_name)
  File "/usr/lib/python2.7/runpy.py", line 72, in _run_code
    exec code in run_globals
  File "/home/ubuntu/RCloud/RCProj/ServerD/echoS.py", line 196, in <module>
    sock.bind(server_address)
  File "/usr/lib/python2.7/socket.py", line 224, in meth
    return getattr(self._sock,name)(*args)
socket.error: [Errno 98] Address already in use
Traceback (most recent call last):
  File "/usr/lib/python2.7/runpy.py", line 162, in _run_module_as_main
    "__main__", fname, loader, pkg_name)
  File "/usr/lib/python2.7/runpy.py", line 72, in _run_code
    exec code in run_globals
  File "/home/ubuntu/RCloud/RCProj/ServerD/echoS.py", line 196, in <module>
    sock.bind(server_address)
  File "/usr/lib/python2.7/socket.py", line 224, in meth
    return getattr(self._sock,name)(*args)
socket.error: [Errno 98] Address already in use
Traceback (most recent call last):
  File "/usr/lib/python2.7/runpy.py", line 162, in _run_module_as_main
    "__main__", fname, loader, pkg_name)
  File "/usr/lib/python2.7/runpy.py", line 72, in _run_code
    exec code in run_globals
  File "/home/ubuntu/RCloud/RCProj/ServerD/echoS.py", line 196, in <module>
    sock.bind(server_address)
  File "/usr/lib/python2.7/socket.py", line 224, in meth
    return getattr(self._sock,name)(*args)
socket.error: [Errno 98] Address already in use
Traceback (most recent call last):
  File "/usr/lib/python2.7/runpy.py", line 162, in _run_module_as_main
    "__main__", fname, loader, pkg_name)
  File "/usr/lib/python2.7/runpy.py", line 72, in _run_code
    exec code in run_globals
  File "/home/ubuntu/RCloud/RCProj/ServerD/echoS.py", line 196, in <module>
    sock.bind(server_address)
  File "/usr/lib/python2.7/socket.py", line 224, in meth
    return getattr(self._sock,name)(*args)
socket.error: [Errno 98] Address already in use
Traceback (most recent call last):
  File "/usr/lib/python2.7/runpy.py", line 162, in _run_module_as_main
    "__main__", fname, loader, pkg_name)
  File "/usr/lib/python2.7/runpy.py", line 72, in _run_code
    exec code in run_globals
  File "/home/ubuntu/RCloud/RCProj/ServerD/echoS.py", line 196, in <module>
    sock.bind(server_address)
  File "/usr/lib/python2.7/socket.py", line 224, in meth
    return getattr(self._sock,name)(*args)
socket.error: [Errno 98] Address already in use
Traceback (most recent call last):
  File "/usr/lib/python2.7/runpy.py", line 162, in _run_module_as_main
    "__main__", fname, loader, pkg_name)
  File "/usr/lib/python2.7/runpy.py", line 72, in _run_code
    exec code in run_globals
  File "/home/ubuntu/RCloud/RCProj/ServerD/echoS.py", line 196, in <module>
    sock.bind(server_address)
  File "/usr/lib/python2.7/socket.py", line 224, in meth
    return getattr(self._sock,name)(*args)
socket.error: [Errno 98] Address already in use
Traceback (most recent call last):
  File "/usr/lib/python2.7/runpy.py", line 162, in _run_module_as_main
    "__main__", fname, loader, pkg_name)
  File "/usr/lib/python2.7/runpy.py", line 72, in _run_code
    exec code in run_globals
  File "/home/ubuntu/RCloud/RCProj/ServerD/echoS.py", line 196, in <module>
    sock.bind(server_address)
  File "/usr/lib/python2.7/socket.py", line 224, in meth
    return getattr(self._sock,name)(*args)
socket.error: [Errno 98] Address already in use
Traceback (most recent call last):
  File "/usr/lib/python2.7/runpy.py", line 162, in _run_module_as_main
    "__main__", fname, loader, pkg_name)
  File "/usr/lib/python2.7/runpy.py", line 72, in _run_code
    exec code in run_globals
  File "/home/ubuntu/RCloud/RCProj/ServerD/echoS.py", line 196, in <module>
    sock.bind(server_address)
  File "/usr/lib/python2.7/socket.py", line 224, in meth
    return getattr(self._sock,name)(*args)
socket.error: [Errno 98] Address already in use
Traceback (most recent call last):
  File "/usr/lib/python2.7/runpy.py", line 162, in _run_module_as_main
    "__main__", fname, loader, pkg_name)
  File "/usr/lib/python2.7/runpy.py", line 72, in _run_code
    exec code in run_globals
  File "/home/ubuntu/RCloud/RCProj/ServerD/echoS.py", line 196, in <module>
    sock.bind(server_address)
  File "/usr/lib/python2.7/socket.py", line 224, in meth
    return getattr(self._sock,name)(*args)
socket.error: [Errno 98] Address already in use
Traceback (most recent call last):
  File "/usr/lib/python2.7/runpy.py", line 162, in _run_module_as_main
    "__main__", fname, loader, pkg_name)
  File "/usr/lib/python2.7/runpy.py", line 72, in _run_code
    exec code in run_globals
  File "/home/ubuntu/RCloud/RCProj/ServerD/echoS.py", line 196, in <module>
    sock.bind(server_address)
  File "/usr/lib/python2.7/socket.py", line 224, in meth
    return getattr(self._sock,name)(*args)
socket.error: [Errno 98] Address already in use
